Workbook

Sheet Overview
A1: Image Asset Tracker
A2: Every asset the recipes use, counted from the recipe data. Change only the yellow Status cells (dropdown); counts update automatically.
A4: Sheet | B4: Assets | C4: Done | D4: In progress / Sketch | E4: To do | F4: % done
A5: Ingredients | B5: =COUNTA(Ingredients!F:F)-1 | C5: =COUNTIF(Ingredients!F:F,"Done") | D5: =COUNTIF(Ingredients!F:F,"In progress")+COUNTIF(Ingredients!F:F,"Sketch") | E5: =COUNTIF(Ingredients!F:F,"To do") | F5: =IF(B5=0,0,C5/B5)
A6: Candles | B6: =COUNTA(Candles!D:D)-1 | C6: =COUNTIF(Candles!D:D,"Done") | D6: =COUNTIF(Candles!D:D,"In progress")+COUNTIF(Candles!D:D,"Sketch") | E6: =COUNTIF(Candles!D:D,"To do") | F6: =IF(B6=0,0,C6/B6)
A7: Tarot | B7: =COUNTA(Tarot!D:D)-1 | C7: =COUNTIF(Tarot!D:D,"Done") | D7: =COUNTIF(Tarot!D:D,"In progress")+COUNTIF(Tarot!D:D,"Sketch") | E7: =COUNTIF(Tarot!D:D,"To do") | F7: =IF(B7=0,0,C7/B7)
A8: Condition Icons | B8: =COUNTA('Condition Icons'!D:D)-1 | C8: =COUNTIF('Condition Icons'!D:D,"Done") | D8: =COUNTIF('Condition Icons'!D:D,"In progress")+COUNTIF('Condition Icons'!D:D,"Sketch") | E8: =COUNTIF('Condition Icons'!D:D,"To do") | F8: =IF(B8=0,0,C8/B8)
A9: Spell Products | B9: =COUNTA('Spell Products'!D:D)-1 | C9: =COUNTIF('Spell Products'!D:D,"Done") | D9: =COUNTIF('Spell Products'!D:D,"In progress")+COUNTIF('Spell Products'!D:D,"Sketch") | E9: =COUNTIF('Spell Products'!D:D,"To do") | F9: =IF(B9=0,0,C9/B9)
A10: Altar, Tools & Books | B10: =COUNTA('Altar, Tools & Books'!D:D)-1 | C10: =COUNTIF('Altar, Tools & Books'!D:D,"Done") | D10: =COUNTIF('Altar, Tools & Books'!D:D,"In progress")+COUNTIF('Altar, Tools & Books'!D:D,"Sketch") | E10: =COUNTIF('Altar, Tools & Books'!D:D,"To do") | F10: =IF(B10=0,0,C10/B10)
A11: Total | B11: =SUM(B5:B10) | C11: =SUM(C5:C10) | D11: =SUM(D5:D10) | E11: =SUM(E5:E10) | F11: =IF(B11=0,0,C11/B11)
A13: Recipe Usage lists every spell–ingredient pair; Recipes lists candle, tarot and conditions for each spell.
A15: Ingredient Feel gives every ingredient a Target (Body / Mind / Space) and a Strength (Gentle / Strong) so ingredients that share a keyword can be told apart. Edit the yellow cells there.
A16: Advice lists the advice questions, one perfect answer each. Its check columns turn red if an Ingredient Feel edit gives a question two perfect answers or none.
A17: Walk-in Plan schedules every recipe no regular orders, once each, across the year; Learning Check compares each regular order's new parts with and without it.
A18: Letters lists the 17 letters that arrive in the post. Each points at a dead end: an ingredient whose needed keyword is hidden, so searching collected words won't find it. Columns give the keyword it names, the first order that needs it, and why that spot is hard. Letters are a side help; every order can be solved without them.

Sheet Recipe Usage
A1: Spell ID | B1: Spell Name | C1: Spell Type | D1: Ingredient (asset) | E1: Recipe wording
A2: 1 | B2: Rosewater Reverie | C2: Potion | D2: Rosewater | E2: Rosewater
A3: 1 | B3: Rosewater Reverie | C3: Potion | D3: Rose petals | E3: rose petals
A4: 1 | B4: Rosewater Reverie | C4: Potion | D4: Strawberry | E4: fresh strawberry
A5: 1 | B5: Rosewater Reverie | C5: Potion | D5: Vanilla | E5: vanilla bean
A6: 1 | B6: Rosewater Reverie | C6: Potion | D6: Honey | E6: honey
A7: 1 | B7: Rosewater Reverie | C7: Potion | D7: Rose quartz | E7: rose quartz
A8: 2 | B8: The Velvet Thread | C8: Charm | D8: Web Dew | E8: Web Dew
A9: 2 | B9: The Velvet Thread | C9: Charm | D9: Velvet ribbon (red) | E9: red velvet ribbon
A10: 2 | B10: The Velvet Thread | C10: Charm | D10: Red thread | E10: red thread
A11: 2 | B11: The Velvet Thread | C11: Charm | D11: Rose quartz | E11: rose quartz
A12: 2 | B12: The Velvet Thread | C12: Charm | D12: Lavender | E12: dried lavender
A13: 2 | B13: The Velvet Thread | C13: Charm | D13: Heart-shaped button | E13: heart-shaped button
... A1114: 240 | B1114: The Glitterbomb Muse | C1114: Powder | D1114: Carnelian | E1114: carnelian

Sheet Recipes
A1: Spell ID | B1: Category | C1: Spell Name | D1: Spell Type | E1: Candle | F1: Tarot | G1: When
A2: 1 | B2: Love, Romance & Attraction | C2: Rosewater Reverie | D2: Potion | E2: Pink | F2: The Lovers | G2: Pink Moon (April full moon)
A3: 2 | B3: Love, Romance & Attraction | C3: The Velvet Thread | D3: Charm | E3: Red | F3: The Lovers | G3: Friday · Waxing Crescent
A4: 3 | B4: Love, Romance & Attraction | C4: Two Hearts, One Hearth | D4: Spell Bottle | E4: Pink | F4: The Lovers | G4: Monday · Full Moon
A5: 4 | B5: Love, Romance & Attraction | C5: Ember of Eden | D5: Oil | E5: Red | F5: The Devil | G5: Tuesday · Full Moon · Sunrise
A6: 5 | B6: Love, Romance & Attraction | C6: Darling, You're Divine | D6: Bath Salt | E6: Pink | F6: The Star | G6: Friday
A7: 6 | B7: Love, Romance & Attraction | C7: Venus in Bloom | D7: Glamour | E7: — | F7: The Empress | G7: Noon · Beltane
A8: 7 | B8: Love, Romance & Attraction | C8: The Blushing Star | D8: Sachet | E8: Pink | F8: The Lovers | G8: Friday · Waxing Crescent
A9: 8 | B9: Love, Romance & Attraction | C9: Heartspeak | D9: Tea | E9: Light blue | F9: Justice | G9: Full Moon
A10: 9 | B10: Love, Romance & Attraction | C10: The Unbinding Rose | D10: Witch's Ladder | E10: Black | F10: Death | G10: Saturday · Waning Moon · Twilight
A11: 10 | B11: Love, Romance & Attraction | C11: Petals After Rain | D11: Balm | E11: Pink | F11: Temperance | G11: Rain · Waning Gibbous
A12: 11 | B12: Love, Romance & Attraction | C12: Strawberry Moon | D12: Cookies | E12: — | F12: — | G12: Strawberry Moon (June full moon)
A13: 12 | B13: Love, Romance & Attraction | C13: The Lover's Mirror | D13: Hand Mirror | E13: Pink | F13: The Empress | G13: Friday · Full Moon
... A241: 240 | B241: Playful & Niche Intentions | C241: The Glitterbomb Muse | D241: Powder | E241: — | F241: The Fool | G241: Thunderstorm

Sheet Ingredients
A1: Ingredient | B1: Category | C1: Where in shop | D1: Used in # spells | E1: Image file | F1: Status | G1: Notes | H1: Look (art brief)
A2: Moonwater | B2: Base waters | C2: Left · Water bottles | D2: =COUNTIF('Recipe Usage'!$D$2:$D$1114,A2) | E2: ing_moonwater.png | F2: To do | H2: clear, with a silvery sheen
A3: Sunwater | B3: Base waters | C3: Left · Water bottles | D3: =COUNTIF('Recipe Usage'!$D$2:$D$1114,A3) | E3: ing_sunwater.png | F3: To do | H3: clear, with a golden glint
A4: Rainwater | B4: Base waters | C4: Left · Water bottles | D4: =COUNTIF('Recipe Usage'!$D$2:$D$1114,A4) | E4: ing_rainwater.png | F4: To do | H4: clear and plain
A5: Dawn dew | B5: Base waters | C5: Left · Water bottles | D5: =COUNTIF('Recipe Usage'!$D$2:$D$1114,A5) | E5: ing_dawn_dew.png | F5: To do | H5: a few clear drops, cool to the touch
A6: Sea Water | B6: Base waters | C6: Left · Water bottles | D6: =COUNTIF('Recipe Usage'!$D$2:$D$1114,A6) | E6: ing_sea_water.png | F6: To do | H6: cloudy and salty
A7: Spring water | B7: Base waters | C7: Left · Water bottles | D7: =COUNTIF('Recipe Usage'!$D$2:$D$1114,A7) | E7: ing_spring_water.png | F7: To do | H7: clear and plain
A8: Rosewater | B8: Base waters | C8: Left · Water bottles | D8: =COUNTIF('Recipe Usage'!$D$2:$D$1114,A8) | E8: ing_rosewater.png | F8: To do | H8: clear, with a pink blush
A9: New Moon Water | B9: Base waters | C9: Left · Water bottles | D9: =COUNTIF('Recipe Usage'!$D$2:$D$1114,A9) | E9: ing_new_moon_water.png | F9: To do | H9: clear, and darker than it should be
A10: Web Dew | B10: Base waters | C10: Left · Water bottles | D10: =COUNTIF('Recipe Usage'!$D$2:$D$1114,A10) | E10: ing_web_dew.png | F10: To do | H10: tiny bright beads on a thread
A11: Snow Water | B11: Base waters | C11: Left · Water bottles | D11: =COUNTIF('Recipe Usage'!$D$2:$D$1114,A11) | E11: ing_snow_water.png | F11: To do | H11: clear and icy
A12: Storm Water | B12: Base waters | C12: Left · Water bottles | D12: =COUNTIF('Recipe Usage'!$D$2:$D$1114,A12) | E12: ing_storm_water.png | F12: To do | H12: grey and restless
A13: Almond oil | B13: Oils, butters & waxes | C13: Left · Kitchen | D13: =COUNTIF('Recipe Usage'!$D$2:$D$1114,A13) | E13: ing_almond_oil.png | F13: To do | H13: pale and golden
... A259: Red paint | B259: Inks & paints | C259: Right · Findings | D259: =COUNTIF('Recipe Usage'!$D$2:$D$1114,A259) | E259: ing_red_paint.png | F259: To do | H259: thick and red

Sheet Ingredient Feel
A1: Ingredient | B1: Category | C1: Properties | D1: Target | E1: Strength | F1: Book line | G1: Same feel as # others | H1: Check | I1: Why / note | J1: Key (helper) | K1: Sorted props (helper) | L1: Props padded (helper)
A2: Moonwater | B2: Base waters | C2: intuition, dreams, release, calm | D2: Mind | E2: Gentle | F2: Drink it by the window before bed. It loosens what the day left behind and carries you somewhere far. | G2: =IF(OR(D2="—",D2="",K2=""),"",COUNTIF($J$2:$J$259,J2)-1) | J2: =K2&"|"&D2&"|"&E2 | K2: calm,dreams,intuition,release | L2: =", "&C2&", "
A3: Sunwater | B3: Base waters | C3: confidence, success, energy, joy, courage | D3: Mind | E3: Strong | F3: Bright and bold. Pours nerve straight into the heart. | G3: =IF(OR(D3="—",D3="",K3=""),"",COUNTIF($J$2:$J$259,J3)-1) | J3: =K3&"|"&D3&"|"&E3 | K3: confidence,courage,energy,joy,success | L3: =", "&C3&", "
A4: Rainwater | B4: Base waters | C4: cleansing, healing, growth | D4: Body | E4: Gentle | F4: Washes and mends gently. Good for tired bodies and new shoots. | G4: =IF(OR(D4="—",D4="",K4=""),"",COUNTIF($J$2:$J$259,J4)-1) | J4: =K4&"|"&D4&"|"&E4 | K4: cleansing,growth,healing | L4: =", "&C4&", "
A5: Dawn dew | B5: Base waters | C5: beauty, beginnings, wonder | D5: Body | E5: Gentle | F5: A morning touch for the skin, and for starting fresh. | G5: =IF(OR(D5="—",D5="",K5=""),"",COUNTIF($J$2:$J$259,J5)-1) | J5: =K5&"|"&D5&"|"&E5 | K5: beauty,beginnings,wonder | L5: =", "&C5&", "
A6: Sea Water | B6: Base waters | C6: release, connection | D6: Space | E6: Strong | F6: Tide and salt. Carries things far away, and it is not gentle about it. | G6: =IF(OR(D6="—",D6="",K6=""),"",COUNTIF($J$2:$J$259,J6)-1) | J6: =K6&"|"&D6&"|"&E6 | K6: connection,release | L6: =", "&C6&", "
A7: Spring water | B7: Base waters | D7: — | E7: — | F7: Base for Potion, Tonic, Water. | G7: =IF(OR(D7="—",D7="",K7=""),"",COUNTIF($J$2:$J$259,J7)-1) | J7: =K7&"|"&D7&"|"&E7 | L7: =", "&C7&", "
A8: Rosewater | B8: Base waters | C8: love, beauty, self-love, confidence | D8: Mind | E8: Gentle | F8: A splash on the face before the mirror, to be kinder to whoever looks back. | G8: =IF(OR(D8="—",D8="",K8=""),"",COUNTIF($J$2:$J$259,J8)-1) | J8: =K8&"|"&D8&"|"&E8 | K8: beauty,confidence,love,self-love | L8: =", "&C8&", "
A9: New Moon Water | B9: Base waters | C9: beginnings, intuition, growth | D9: Mind | E9: Gentle | F9: For a plan you haven't told anyone about yet. | G9: =IF(OR(D9="—",D9="",K9=""),"",COUNTIF($J$2:$J$259,J9)-1) | J9: =K9&"|"&D9&"|"&E9 | K9: beginnings,growth,intuition | L9: =", "&C9&", "
A10: Web Dew | B10: Base waters | C10: connection, attraction, wonder | D10: Space | E10: Gentle | F10: Strung between things. It ties one person to another. | G10: =IF(OR(D10="—",D10="",K10=""),"",COUNTIF($J$2:$J$259,J10)-1) | J10: =K10&"|"&D10&"|"&E10 | K10: attraction,connection,wonder | L10: =", "&C10&", "
A11: Snow Water | B11: Base waters | C11: rest, calm, cleansing | D11: Body | E11: Gentle | F11: Hushes the body, like a house after snowfall. | G11: =IF(OR(D11="—",D11="",K11=""),"",COUNTIF($J$2:$J$259,J11)-1) | J11: =K11&"|"&D11&"|"&E11 | K11: calm,cleansing,rest | L11: =", "&C11&", "
A12: Storm Water | B12: Base waters | C12: energy, creativity | D12: Mind | E12: Strong | F12: Raw, crackling force for a stuck mind. | G12: =IF(OR(D12="—",D12="",K12=""),"",COUNTIF($J$2:$J$259,J12)-1) | J12: =K12&"|"&D12&"|"&E12 | K12: creativity,energy | L12: =", "&C12&", "
A13: Almond oil | B13: Oils, butters & waxes | D13: — | E13: — | F13: Base for Oil, Glamour, Balm. | G13: =IF(OR(D13="—",D13="",K13=""),"",COUNTIF($J$2:$J$259,J13)-1) | J13: =K13&"|"&D13&"|"&E13 | L13: =", "&C13&", "
A14: Jojoba oil | B14: Oils, butters & waxes | D14: — | E14: — | F14: Base for Oil, Glamour. | G14: =IF(OR(D14="—",D14="",K14=""),"",COUNTIF($J$2:$J$259,J14)-1) | J14: =K14&"|"&D14&"|"&E14 | L14: =", "&C14&", "
A15: Olive oil | B15: Oils, butters & waxes | D15: — | E15: — | F15: Base for Oil. | G15: =IF(OR(D15="—",D15="",K15=""),"",COUNTIF($J$2:$J$259,J15)-1) | J15: =K15&"|"&D15&"|"&E15 | L15: =", "&C15&", "
A16: Sunflower oil | B16: Oils, butters & waxes | D16: — | E16: — | F16: Base for Oil, Glamour. | G16: =IF(OR(D16="—",D16="",K16=""),"",COUNTIF($J$2:$J$259,J16)-1) | J16: =K16&"|"&D16&"|"&E16 | L16: =", "&C16&", "
A17: Shea butter | B17: Oils, butters & waxes | D17: — | E17: — | F17: Base for Balm. | G17: =IF(OR(D17="—",D17="",K17=""),"",COUNTIF($J$2:$J$259,J17)-1) | J17: =K17&"|"&D17&"|"&E17 | L17: =", "&C17&", "
A18: Beeswax | B18: Oils, butters & waxes | D18: — | E18: — | F18: Base for Balm. | G18: =IF(OR(D18="—",D18="",K18=""),"",COUNTIF($J$2:$J$259,J18)-1) | J18: =K18&"|"&D18&"|"&E18 | L18: =", "&C18&", "
A19: Butter | B19: Oils, butters & waxes | D19: — | E19: — | F19: Base for Butter, Cookies. | G19: =IF(OR(D19="—",D19="",K19=""),"",COUNTIF($J$2:$J$259,J19)-1) | J19: =K19&"|"&D19&"|"&E19 | L19: =", "&C19&", "
A20: Angelica root | B20: Herbs & flowers | C20: protection, healing, release | D20: Space | E20: Strong | F20: Guards the doorway and drives out whatever lingers. Not for skin. | G20: =IF(OR(D20="—",D20="",K20=""),"",COUNTIF($J$2:$J$259,J20)-1) | J20: =K20&"|"&D20&"|"&E20 | K20: healing,protection,release | L20: =", "&C20&", "
A21: Basil | B21: Herbs & flowers | C21: abundance, luck | D21: Space | E21: Gentle | F21: A pot on the windowsill invites plenty into the house. | G21: =IF(OR(D21="—",D21="",K21=""),"",COUNTIF($J$2:$J$259,J21)-1) | J21: =K21&"|"&D21&"|"&E21 | K21: abundance,luck | L21: =", "&C21&", "
A22: Bay leaf | B22: Herbs & flowers | C22: success, protection, luck, release | D22: Space | E22: Strong | F22: Write on it and burn it: wins, wards and send-offs. | G22: =IF(OR(D22="—",D22="",K22=""),"",COUNTIF($J$2:$J$259,J22)-1) | J22: =K22&"|"&D22&"|"&E22 | K22: luck,protection,release,success | L22: =", "&C22&", "
A23: Calendula | B23: Herbs & flowers | C23: healing, joy, confidence | D23: Body | E23: Gentle | F23: For scraped knees and sore skin. The gentlest healer on the shelf. | G23: =IF(OR(D23="—",D23="",K23=""),"",COUNTIF($J$2:$J$259,J23)-1) | J23: =K23&"|"&D23&"|"&E23 | K23: confidence,healing,joy | L23: =", "&C23&", "
A24: Chamomile | B24: Herbs & flowers | C24: calm, comfort, sleep, healing | D24: Mind | E24: Gentle | F24: For the child who lies awake worrying. Mild as warm milk. | G24: =IF(OR(D24="—",D24="",K24=""),"",COUNTIF($J$2:$J$259,J24)-1) | J24: =K24&"|"&D24&"|"&E24 | K24: calm,comfort,healing,sleep | L24: =", "&C24&", "
A25: Clover | B25: Herbs & flowers | C25: luck, friendship, joy | D25: Space | E25: Gentle | F25: Small, everyday good fortune, shared between friends. | G25: =IF(OR(D25="—",D25="",K25=""),"",COUNTIF($J$2:$J$259,J25)-1) | J25: =K25&"|"&D25&"|"&E25 | K25: friendship,joy,luck | L25: =", "&C25&", "
A26: Comfrey leaf | B26: Herbs & flowers | C26: travel, protection | D26: Space | E26: Gentle | F26: Tucked into a shoe for a safe road. | G26: =IF(OR(D26="—",D26="",K26=""),"",COUNTIF($J$2:$J$259,J26)-1) | H26: OK | I26: Kept as a travel herb, matching its spellbook entry. The scraped-hand answer is calendula alone. | J26: =K26&"|"&D26&"|"&E26 | K26: protection,travel | L26: =", "&C26&", "
A27: Cornflower | B27: Herbs & flowers | C27: calm, intuition | D27: Mind | E27: Gentle | F27: Clears the mind's eye like a blue sky after a muddle. | G27: =IF(OR(D27="—",D27="",K27=""),"",COUNTIF($J$2:$J$259,J27)-1) | J27: =K27&"|"&D27&"|"&E27 | K27: calm,intuition | L27: =", "&C27&", "
A28: Daisy | B28: Herbs & flowers | C28: joy, friendship, beginnings | D28: Mind | E28: Gentle | F28: A chain of them for a new classmate on the first day of school. | G28: =IF(OR(D28="—",D28="",K28=""),"",COUNTIF($J$2:$J$259,J28)-1) | J28: =K28&"|"&D28&"|"&E28 | K28: beginnings,friendship,joy | L28: =", "&C28&", "
A29: Dandelion | B29: Herbs & flowers | C29: wonder, joy, beginnings | D29: Mind | E29: Gentle | F29: Blow it and make a wish. Childlike amazement. | G29: =IF(OR(D29="—",D29="",K29=""),"",COUNTIF($J$2:$J$259,J29)-1) | J29: =K29&"|"&D29&"|"&E29 | K29: beginnings,joy,wonder | L29: =", "&C29&", "
A30: Dandelion root | B30: Herbs & flowers | C30: release, cleansing, healing | D30: Mind | E30: Strong | F30: Digs out what you've been holding on to. Bitter, but thorough. | G30: =IF(OR(D30="—",D30="",K30=""),"",COUNTIF($J$2:$J$259,J30)-1) | I30: Moved from Body/Gentle so calendula is the only gentle body healer among the herbs. | J30: =K30&"|"&D30&"|"&E30 | K30: cleansing,healing,release | L30: =", "&C30&", "
A31: Elderflower | B31: Herbs & flowers | C31: joy, wonder | D31: Mind | E31: Gentle | F31: Light and sparkling, like cordial at a garden party. | G31: =IF(OR(D31="—",D31="",K31=""),"",COUNTIF($J$2:$J$259,J31)-1) | J31: =K31&"|"&D31&"|"&E31 | K31: joy,wonder | L31: =", "&C31&", "
A32: Eucalyptus | B32: Herbs & flowers | C32: cleansing, healing, release | D32: Body | E32: Strong | F32: Opens the chest and clears the breath. Sharp, for colds. | G32: =IF(OR(D32="—",D32="",K32=""),"",COUNTIF($J$2:$J$259,J32)-1) | J32: =K32&"|"&D32&"|"&E32 | K32: cleansing,healing,release | L32: =", "&C32&", "
A33: Fern | B33: Herbs & flowers | C33: connection, growth | D33: Space | E33: Gentle | F33: Spreads quietly underfoot and links one place to the next. | G33: =IF(OR(D33="—",D33="",K33=""),"",COUNTIF($J$2:$J$259,J33)-1) | J33: =K33&"|"&D33&"|"&E33 | K33: connection,growth | L33: =", "&C33&", "
A34: Four-leaf clover | B34: Herbs & flowers | C34: luck, opportunity, joy | D34: Space | E34: Strong | F34: Rare and potent fortune. Opens doors that were shut. | G34: =IF(OR(D34="—",D34="",K34=""),"",COUNTIF($J$2:$J$259,J34)-1) | J34: =K34&"|"&D34&"|"&E34 | K34: joy,luck,opportunity | L34: =", "&C34&", "
A35: Garden sage | B35: Herbs & flowers | C35: cleansing, truth, protection | D35: Space | E35: Strong | F35: Smoke that clears a room and leaves no space for lies. | G35: =IF(OR(D35="—",D35="",K35=""),"",COUNTIF($J$2:$J$259,J35)-1) | J35: =K35&"|"&D35&"|"&E35 | K35: cleansing,protection,truth | L35: =", "&C35&", "
A36: Hibiscus | B36: Herbs & flowers | C36: passion, love, beauty | D36: Body | E36: Strong | F36: Hot-blooded. A fire you can feel in your cheeks. | G36: =IF(OR(D36="—",D36="",K36=""),"",COUNTIF($J$2:$J$259,J36)-1) | J36: =K36&"|"&D36&"|"&E36 | K36: beauty,love,passion | L36: =", "&C36&", "
A37: Hops | B37: Herbs & flowers | C37: sleep, rest, calm | D37: Body | E37: Gentle | F37: Heavy-lidded and gentle. Brings the body down for the night. | G37: =IF(OR(D37="—",D37="",K37=""),"",COUNTIF($J$2:$J$259,J37)-1) | J37: =K37&"|"&D37&"|"&E37 | K37: calm,rest,sleep | L37: =", "&C37&", "
A38: Jasmine | B38: Herbs & flowers | C38: dreams, beauty, intuition | D38: Mind | E38: Gentle | F38: Opens at night. Sweetens the hours between lying down and drifting off. | G38: =IF(OR(D38="—",D38="",K38=""),"",COUNTIF($J$2:$J$259,J38)-1) | J38: =K38&"|"&D38&"|"&E38 | K38: beauty,dreams,intuition | L38: =", "&C38&", "
A39: Lavender | B39: Herbs & flowers | C39: calm, sleep, cleansing, love, joy | D39: Mind | E39: Gentle | F39: The great soother. For an evening that won't settle, a pillow, a drawer, a note to a sweetheart. | G39: =IF(OR(D39="—",D39="",K39=""),"",COUNTIF($J$2:$J$259,J39)-1) | J39: =K39&"|"&D39&"|"&E39 | K39: calm,cleansing,joy,love,sleep | L39: =", "&C39&", "
A40: Lemon balm | B40: Herbs & flowers | C40: calm, healing, communication | D40: Mind | E40: Gentle | F40: For the nervous stammer, and the worry underneath it. | G40: =IF(OR(D40="—",D40="",K40=""),"",COUNTIF($J$2:$J$259,J40)-1) | J40: =K40&"|"&D40&"|"&E40 | K40: calm,communication,healing | L40: =", "&C40&", "
...

Sheet Advice
A1: # | B1: Asker | C1: Question | D1: Asks for | E1: Keyword | F1: Target | G1: Strength | H1: Perfect answer | I1: Clue words | J1: Perfect matches | K1: Answer fits? | L1: Good answers (#) | M1: Good answers (names)
A2: 1 | B2: Rosalind | C2: My youngest scraped a hand on the garden wall. Which herb helps it heal? Nothing that stings. | D2: Herbs & flowers | E2: healing | F2: Body | G2: Gentle | H2: Calendula | I2: "heal" = healing; a hand = Body; "nothing that stings" = Gentle | J2: =COUNTIFS('Ingredient Feel'!$L$2:$L$259,"*, "&E2&", *",'Ingredient Feel'!$B$2:$B$259,D2,'Ingredient Feel'!$D$2:$D$259,F2,'Ingredient Feel'!$E$2:$E$259,G2) | K2: =IF(COUNTIFS('Ingredient Feel'!$A$2:$A$259,H2,'Ingredient Feel'!$L$2:$L$259,"*, "&E2&", *",'Ingredient Feel'!$D$2:$D$259,F2,'Ingredient Feel'!$E$2:$E$259,G2)=1,"Yes","No") | L2: =COUNTIFS('Ingredient Feel'!$L$2:$L$259,"*, "&E2&", *",'Ingredient Feel'!$B$2:$B$259,D2)-J2 | M2: Angelica root, Chamomile, Dandelion root, Eucalyptus, Lemon balm, Nettle, Rose, Seaweed
A3: 2 | B3: Parent with children | C3: My husband hasn't slept properly in a week. Is there a herb that will actually knock him out? | D3: Herbs & flowers | E3: sleep | F3: Body | G3: Strong | H3: Valerian | I3: "slept" = sleep; tired body; "knock him out" = Strong | J3: =COUNTIFS('Ingredient Feel'!$L$2:$L$259,"*, "&E3&", *",'Ingredient Feel'!$B$2:$B$259,D3,'Ingredient Feel'!$D$2:$D$259,F3,'Ingredient Feel'!$E$2:$E$259,G3) | K3: =IF(COUNTIFS('Ingredient Feel'!$A$2:$A$259,H3,'Ingredient Feel'!$L$2:$L$259,"*, "&E3&", *",'Ingredient Feel'!$D$2:$D$259,F3,'Ingredient Feel'!$E$2:$E$259,G3)=1,"Yes","No") | L3: =COUNTIFS('Ingredient Feel'!$L$2:$L$259,"*, "&E3&", *",'Ingredient Feel'!$B$2:$B$259,D3)-J3 | M3: Chamomile, Hops, Lavender
A4: 3 | B4: Walk-in | C4: I've just woken from a long nap and feel like cotton wool. Something to freshen me up, but not too sharp? | D4: Herbs & flowers | E4: energy | F4: Body | G4: Gentle | H4: Mint | I4: "freshen me up" = energy; groggy body; "not too sharp" = Gentle | J4: =COUNTIFS('Ingredient Feel'!$L$2:$L$259,"*, "&E4&", *",'Ingredient Feel'!$B$2:$B$259,D4,'Ingredient Feel'!$D$2:$D$259,F4,'Ingredient Feel'!$E$2:$E$259,G4) | K4: =IF(COUNTIFS('Ingredient Feel'!$A$2:$A$259,H4,'Ingredient Feel'!$L$2:$L$259,"*, "&E4&", *",'Ingredient Feel'!$D$2:$D$259,F4,'Ingredient Feel'!$E$2:$E$259,G4)=1,"Yes","No") | L4: =COUNTIFS('Ingredient Feel'!$L$2:$L$259,"*, "&E4&", *",'Ingredient Feel'!$B$2:$B$259,D4)-J4 | M4: Lemongrass, Peppermint, Black tea
A5: 4 | B5: Noor | C5: I've got a presentation in an hour and my head is mush. What wakes up the brain, fast? | D5: Herbs & flowers | E5: energy | F5: Mind | G5: Strong | H5: Peppermint | I5: "wakes up" = energy; "the brain" = Mind; "fast" = Strong | J5: =COUNTIFS('Ingredient Feel'!$L$2:$L$259,"*, "&E5&", *",'Ingredient Feel'!$B$2:$B$259,D5,'Ingredient Feel'!$D$2:$D$259,F5,'Ingredient Feel'!$E$2:$E$259,G5) | K5: =IF(COUNTIFS('Ingredient Feel'!$A$2:$A$259,H5,'Ingredient Feel'!$L$2:$L$259,"*, "&E5&", *",'Ingredient Feel'!$D$2:$D$259,F5,'Ingredient Feel'!$E$2:$E$259,G5)=1,"Yes","No") | L5: =COUNTIFS('Ingredient Feel'!$L$2:$L$259,"*, "&E5&", *",'Ingredient Feel'!$B$2:$B$259,D5)-J5 | M5: Lemongrass, Mint, Black tea
A6: 5 | B6: Walk-in | C6: I want to go really deep when I meditate. Which flower quiets the mind all the way down? | D6: Herbs & flowers | E6: calm | F6: Mind | G6: Strong | H6: Lotus | I6: "quiets" = calm; "the mind" = Mind; "really deep, all the way" = Strong | J6: =COUNTIFS('Ingredient Feel'!$L$2:$L$259,"*, "&E6&", *",'Ingredient Feel'!$B$2:$B$259,D6,'Ingredient Feel'!$D$2:$D$259,F6,'Ingredient Feel'!$E$2:$E$259,G6) | K6: =IF(COUNTIFS('Ingredient Feel'!$A$2:$A$259,H6,'Ingredient Feel'!$L$2:$L$259,"*, "&E6&", *",'Ingredient Feel'!$D$2:$D$259,F6,'Ingredient Feel'!$E$2:$E$259,G6)=1,"Yes","No") | L6: =COUNTIFS('Ingredient Feel'!$L$2:$L$259,"*, "&E6&", *",'Ingredient Feel'!$B$2:$B$259,D6)-J6 | M6: Chamomile, Cornflower, Hops, Lavender, Lemon balm, Mint, Valerian, White lily
A7: 6 | B7: Walk-in | C7: Our old dog died last week. Is there a herb that helps you let go, gently? | D7: Herbs & flowers | E7: release | F7: Mind | G7: Gentle | H7: Cypress | I7: "let go" = release; grief = Mind; "gently" = Gentle | J7: =COUNTIFS('Ingredient Feel'!$L$2:$L$259,"*, "&E7&", *",'Ingredient Feel'!$B$2:$B$259,D7,'Ingredient Feel'!$D$2:$D$259,F7,'Ingredient Feel'!$E$2:$E$259,G7) | K7: =IF(COUNTIFS('Ingredient Feel'!$A$2:$A$259,H7,'Ingredient Feel'!$L$2:$L$259,"*, "&E7&", *",'Ingredient Feel'!$D$2:$D$259,F7,'Ingredient Feel'!$E$2:$E$259,G7)=1,"Yes","No") | L7: =COUNTIFS('Ingredient Feel'!$L$2:$L$259,"*, "&E7&", *",'Ingredient Feel'!$B$2:$B$259,D7)-J7 | M7: Angelica root, Bay leaf, Dandelion root, Eucalyptus, Rose thorns, Seaweed, Willow bark
A8: 7 | B8: Walk-in | C8: This cold has my chest completely blocked. What clears it out? | D8: Herbs & flowers | E8: cleansing | F8: Body | G8: Strong | H8: Eucalyptus | I8: "clears it out" = cleansing; chest = Body; "completely blocked" = Strong | J8: =COUNTIFS('Ingredient Feel'!$L$2:$L$259,"*, "&E8&", *",'Ingredient Feel'!$B$2:$B$259,D8,'Ingredient Feel'!$D$2:$D$259,F8,'Ingredient Feel'!$E$2:$E$259,G8) | K8: =IF(COUNTIFS('Ingredient Feel'!$A$2:$A$259,H8,'Ingredient Feel'!$L$2:$L$259,"*, "&E8&", *",'Ingredient Feel'!$D$2:$D$259,F8,'Ingredient Feel'!$E$2:$E$259,G8)=1,"Yes","No") | L8: =COUNTIFS('Ingredient Feel'!$L$2:$L$259,"*, "&E8&", *",'Ingredient Feel'!$B$2:$B$259,D8)-J8 | M8: Dandelion root, Garden sage, Lavender, Mint, Rosemary, Cedar, Juniper
A9: 8 | B9: Edmund | C9: My brother keeps forgetting names. Something properly strong for the memory? | D9: Herbs & flowers | E9: memory | F9: Mind | G9: Strong | H9: Rosemary | I9: "memory" = memory; names = Mind; "properly strong" = Strong | J9: =COUNTIFS('Ingredient Feel'!$L$2:$L$259,"*, "&E9&", *",'Ingredient Feel'!$B$2:$B$259,D9,'Ingredient Feel'!$D$2:$D$259,F9,'Ingredient Feel'!$E$2:$E$259,G9) | K9: =IF(COUNTIFS('Ingredient Feel'!$A$2:$A$259,H9,'Ingredient Feel'!$L$2:$L$259,"*, "&E9&", *",'Ingredient Feel'!$D$2:$D$259,F9,'Ingredient Feel'!$E$2:$E$259,G9)=1,"Yes","No") | L9: =COUNTIFS('Ingredient Feel'!$L$2:$L$259,"*, "&E9&", *",'Ingredient Feel'!$B$2:$B$259,D9)-J9 | M9: Lilac, Pressed moon petals
A10: 9 | B10: Couple | C10: I'm writing a love letter. Which herb makes the words impossible to resist? | D10: Herbs & flowers | E10: love | F10: Mind | G10: Strong | H10: Orris root | I10: "love letter" = love; words = Mind; "impossible to resist" = Strong | J10: =COUNTIFS('Ingredient Feel'!$L$2:$L$259,"*, "&E10&", *",'Ingredient Feel'!$B$2:$B$259,D10,'Ingredient Feel'!$D$2:$D$259,F10,'Ingredient Feel'!$E$2:$E$259,G10) | K10: =IF(COUNTIFS('Ingredient Feel'!$A$2:$A$259,H10,'Ingredient Feel'!$L$2:$L$259,"*, "&E10&", *",'Ingredient Feel'!$D$2:$D$259,F10,'Ingredient Feel'!$E$2:$E$259,G10)=1,"Yes","No") | L10: =COUNTIFS('Ingredient Feel'!$L$2:$L$259,"*, "&E10&", *",'Ingredient Feel'!$B$2:$B$259,D10)-J10 | M10: Hibiscus, Lavender, Rose petals, Rosebud
A11: 10 | B11: Couple | C11: We've been married twenty years. Something to bring the heat back? | D11: Herbs & flowers | E11: love | F11: Body | G11: Strong | H11: Hibiscus | I11: romance = love; "heat" = Body; "bring the heat back" = Strong | J11: =COUNTIFS('Ingredient Feel'!$L$2:$L$259,"*, "&E11&", *",'Ingredient Feel'!$B$2:$B$259,D11,'Ingredient Feel'!$D$2:$D$259,F11,'Ingredient Feel'!$E$2:$E$259,G11) | K11: =IF(COUNTIFS('Ingredient Feel'!$A$2:$A$259,H11,'Ingredient Feel'!$L$2:$L$259,"*, "&E11&", *",'Ingredient Feel'!$D$2:$D$259,F11,'Ingredient Feel'!$E$2:$E$259,G11)=1,"Yes","No") | L11: =COUNTIFS('Ingredient Feel'!$L$2:$L$259,"*, "&E11&", *",'Ingredient Feel'!$B$2:$B$259,D11)-J11 | M11: Lavender, Orris root, Rose petals, Rosebud
A12: 11 | B12: Walk-in | C12: My son is backpacking for a month. A gentle herb to keep him safe on the road? | D12: Herbs & flowers | E12: protection | F12: Space | G12: Gentle | H12: Comfrey leaf | I12: "keep him safe" = protection; "on the road" = Space; "gentle" = Gentle | J12: =COUNTIFS('Ingredient Feel'!$L$2:$L$259,"*, "&E12&", *",'Ingredient Feel'!$B$2:$B$259,D12,'Ingredient Feel'!$D$2:$D$259,F12,'Ingredient Feel'!$E$2:$E$259,G12) | K12: =IF(COUNTIFS('Ingredient Feel'!$A$2:$A$259,H12,'Ingredient Feel'!$L$2:$L$259,"*, "&E12&", *",'Ingredient Feel'!$D$2:$D$259,F12,'Ingredient Feel'!$E$2:$E$259,G12)=1,"Yes","No") | L12: =COUNTIFS('Ingredient Feel'!$L$2:$L$259,"*, "&E12&", *",'Ingredient Feel'!$B$2:$B$259,D12)-J12 | M12: Angelica root, Bay leaf, Garden sage, Mugwort, Rosemary, Rue, Cedar, Juniper
A13: 12 | B13: Walk-in | C13: Since Gran was ill the whole house feels sick. What drives that out? | D13: Herbs & flowers | E13: healing | F13: Space | G13: Strong | H13: Angelica root | I13: "feels sick" = healing; "the whole house" = Space; "drives that out" = Strong | J13: =COUNTIFS('Ingredient Feel'!$L$2:$L$259,"*, "&E13&", *",'Ingredient Feel'!$B$2:$B$259,D13,'Ingredient Feel'!$D$2:$D$259,F13,'Ingredient Feel'!$E$2:$E$259,G13) | K13: =IF(COUNTIFS('Ingredient Feel'!$A$2:$A$259,H13,'Ingredient Feel'!$L$2:$L$259,"*, "&E13&", *",'Ingredient Feel'!$D$2:$D$259,F13,'Ingredient Feel'!$E$2:$E$259,G13)=1,"Yes","No") | L13: =COUNTIFS('Ingredient Feel'!$L$2:$L$259,"*, "&E13&", *",'Ingredient Feel'!$B$2:$B$259,D13)-J13 | M13: Calendula, Chamomile, Dandelion root, Eucalyptus, Lemon balm, Nettle, Rose, Seaweed
... A28: 27 | B28: Parent with children | C28: My daughter's homework is chaos. A gentle stone to help her think in order? | D28: Crystals | E28: focus | F28: Mind | G28: Gentle | H28: Fluorite | I28: "think in order" = focus; thinking = Mind; "gentle", a child = Gentle | J28: =COUNTIFS('Ingredient Feel'!$L$2:$L$259,"*, "&E28&", *",'Ingredient Feel'!$B$2:$B$259,D28,'Ingredient Feel'!$D$2:$D$259,F28,'Ingredient Feel'!$E$2:$E$259,G28) | K28: =IF(COUNTIFS('Ingredient Feel'!$A$2:$A$259,H28,'Ingredient Feel'!$L$2:$L$259,"*, "&E28&", *",'Ingredient Feel'!$D$2:$D$259,F28,'Ingredient Feel'!$E$2:$E$259,G28)=1,"Yes","No") | L28: =COUNTIFS('Ingredient Feel'!$L$2:$L$259,"*, "&E28&", *",'Ingredient Feel'!$B$2:$B$259,D28)-J28 | M28: Clear quartz, Hematite

Sheet Walk-in Plan
A1: Day | B1: Month | C1: Weekday | D1: Moon | E1: Weather | F1: Hour | G1: Shares hour | H1: # | I1: Recipe | J1: Type | K1: When | L1: New (#) | M1: New things | N1: Reuses (#) | O1: Prepares for | P1: Note
A2: 1 | B2: November | C2: Saturday | D2: Waning Gibbous | E2: Cloudy | F2: Noon | H2: 179 | I2: The Path of Least Fuss | J2: Charm | K2: Any time | L2: =IF(M2="",0,LEN(M2)-LEN(SUBSTITUTE(M2,",",""))+1) | M2: Blue thread, Small key | N2: 1 | P2: Week one (fixed)
A3: 1 | B3: November | C3: Saturday | D3: Waning Gibbous | E3: Cloudy | F3: Nightfall | H3: 194 | I3: The Inner Housekeeper | J3: Tea | K3: Any time | L3: =IF(M3="",0,LEN(M3)-LEN(SUBSTITUTE(M3,",",""))+1) | M3: Milk powder, Nettle | N3: 1 | P3: Week one (fixed)
A4: 2 | B4: November | C4: Sunday | D4: Waning Crescent | E4: Rain | F4: Sunrise | H4: 202 | I4: The Unconditional Pillow | J4: Butter | K4: Sunday | L4: =IF(M4="",0,LEN(M4)-LEN(SUBSTITUTE(M4,",",""))+1) | M4: Honey, Rose petals | N4: 1 | O4: Goldie #58 | P4: Week one (fixed)
A5: 3 | B5: November | C5: Monday | D5: New Moon | E5: Windy | F5: Twilight | H5: 181 | I5: The Pattern Beneath | J5: Hand Mirror | K5: New Moon | L5: =IF(M5="",0,LEN(M5)-LEN(SUBSTITUTE(M5,",",""))+1) | M5: Moth wing dust, Mugwort, The Moon | N5: 4 | P5: Week one (fixed)
A6: 4 | B6: November | C6: Tuesday | D6: Waxing Crescent | E6: Thunderstorm | F6: Twilight | H6: 49 | I6: The Unmasked Self | J6: Sigil | K6: Any time | L6: =IF(M6="",0,LEN(M6)-LEN(SUBSTITUTE(M6,",",""))+1) | M6: Licorice root, Rhodonite, Blue candle, The Sun | N6: 0 | O6: Goldie #58 | P6: Week one (fixed)
A7: 5 | B7: November | C7: Wednesday | D7: Waxing Gibbous | E7: Fog / Mist | F7: Sunrise | H7: 164 | I7: The Desk of Possibilities | J7: Incense | K7: Wednesday | L7: =IF(M7="",0,LEN(M7)-LEN(SUBSTITUTE(M7,",",""))+1) | M7: Frankincense, Lemongrass | N7: 3 | P7: Week one (fixed)
A8: 6 | B8: November | C8: Thursday | D8: Full Moon | E8: Clear & sunny | F8: Sunrise | H8: 25 | I8: The Keeper's Knot | J8: Witch's Ladder | K8: Beaver Moon (November full moon) | L8: =IF(M8="",0,LEN(M8)-LEN(SUBSTITUTE(M8,",",""))+1) | M8: Black thread, Brass button, Juniper, Shed cat whisker, White thread, Brown candle, Beaver Moon | N8: 1 | O8: Rosalind #23 | P8: Week one (fixed): only Beaver Moon of the year, a stretch goal
A9: 6 | B9: November | C9: Thursday | D9: Full Moon | E9: Clear & sunny | F9: Twilight | H9: 236 | I9: The Next Obsession | J9: Potion | K9: Any time | L9: =IF(M9="",0,LEN(M9)-LEN(SUBSTITUTE(M9,",",""))+1) | M9: Cherry, Vanilla, The Fool | N9: 1 | P9: Week one (fixed)
A10: 8 | B10: November | C10: Saturday | D10: Waning Crescent | E10: Clear & sunny | F10: Noon | H10: 73 | I10: The Gentle No | J10: Soap | K10: Saturday · Waning Moon | L10: =IF(M10="",0,LEN(M10)-LEN(SUBSTITUTE(M10,",",""))+1) | M10: Amazonite, Garden sage, Lemon, Justice | N10: 3 | O10: Dottie #161, Morwenna #21
A11: 9 | B11: December | C11: Sunday | D11: New Moon | E11: Rain | F11: Noon | H11: 183 | I11: The Hand on the Wheel | J11: Talisman | K11: Sunday · Noon | L11: =IF(M11="",0,LEN(M11)-LEN(SUBSTITUTE(M11,",",""))+1) | M11: Cinnamon, Tiger's eye, Gold candle, The Chariot | N11: 2 | O11: Morwenna #21
A12: 9 | B12: December | C12: Sunday | D12: New Moon | E12: Rain | F12: Twilight | H12: 180 | I12: The Little Victory Bell | J12: Powder | K12: Twilight | L12: =IF(M12="",0,LEN(M12)-LEN(SUBSTITUTE(M12,",",""))+1) | M12: Gold mica, Orange peel | N12: 2 | O12: Hester #68
A13: 10 | B13: December | C13: Monday | D13: Waxing Crescent | E13: Windy | F13: Sunrise | H13: 144 | I13: The Sun's Little Promise | J13: Charm | K13: Yule · Sunrise | L13: =IF(M13="",0,LEN(M13)-LEN(SUBSTITUTE(M13,",",""))+1) | M13: Orange, Patchwork scraps, Sunstone, Yule | N13: 4 | O13: Hester #68
A14: 10 | B14: December | C14: Monday | D14: Waxing Crescent | E14: Windy | F14: Noon | H14: 136 | I14: The Wintering Star | J14: Butter | K14: Yule | L14: =IF(M14="",0,LEN(M14)-LEN(SUBSTITUTE(M14,",",""))+1) | M14: Clove, Nutmeg | N14: 4
A15: 11 | B15: December | C15: Tuesday | D15: Waxing Gibbous | E15: Clear & sunny | F15: Sunrise | H15: 129 | I15: Sunrise in a Teacup | J15: Potion | K15: Sunrise | L15: =IF(M15="",0,LEN(M15)-LEN(SUBSTITUTE(M15,",",""))+1) | M15: Dandelion, Dawn dew | N15: 7
A16: 11 | B16: December | C16: Tuesday | D16: Waxing Gibbous | E16: Clear & sunny | F16: Noon | H16: 50 | I16: The Scarlet Entrance | J16: Oil | K16: Tuesday · Waxing Moon | L16: =IF(M16="",0,LEN(M16)-LEN(SUBSTITUTE(M16,",",""))+1) | M16: Black pepper, Garnet, Red candle | N16: 5
A17: 12 | B17: December | C17: Wednesday | D17: Full Moon | E17: Cloudy | F17: Sunrise | H17: 65 | I17: Words Like Honey | J17: Tea | K17: Wednesday | L17: =IF(M17="",0,LEN(M17)-LEN(SUBSTITUTE(M17,",",""))+1) | M17: Sweet pea, The Lovers | N17: 5 | O17: Hester #68
A18: 12 | B18: December | C18: Wednesday | D18: Full Moon | E18: Cloudy | F18: Sunrise | H18: 165 | I18: The Solitude Sweetspot | J18: Tea | K18: Cold Moon (December full moon) | L18: =IF(M18="",0,LEN(M18)-LEN(SUBSTITUTE(M18,",",""))+1) | M18: Bergamot, Black tea, Rose, Cold Moon | N18: 2
A19: 13 | B19: December | C19: Thursday | D19: Waning Gibbous | E19: Snow | F19: Sunrise | H19: 214 | I19: The Main-Character Morning | J19: Potion | K19: Sunrise | L19: =IF(M19="",0,LEN(M19)-LEN(SUBSTITUTE(M19,",",""))+1) | M19: Strawberry, Orange candle | N19: 5 | O19: Felix #151
A20: 13 | B20: December | C20: Thursday | D20: Waning Gibbous | E20: Snow | F20: Noon | H20: 233 | I20: The Casual Enchantment | J20: Glamour | K20: Any time | L20: =IF(M20="",0,LEN(M20)-LEN(SUBSTITUTE(M20,",",""))+1) | M20: Mint, Rosewater | N20: 1 | O20: Felix #151
A21: 14 | B21: December | C21: Friday | D21: Waning Crescent | E21: Snow | F21: Sunrise | H21: 205 | I21: The Empty Frame | J21: Water | K21: Waning Moon | L21: =IF(M21="",0,LEN(M21)-LEN(SUBSTITUTE(M21,",",""))+1) | N21: 5
A22: 14 | B22: December | C22: Friday | D22: Waning Crescent | E22: Snow | F22: Noon | H22: 168 | I22: The Waiting Room Oracle | J22: Rune | K22: Any time | L22: =IF(M22="",0,LEN(M22)-LEN(SUBSTITUTE(M22,",",""))+1) | M22: Howlite, River stone, The Hanged Man | N22: 1
A23: 15 | B23: January | C23: Saturday | D23: New Moon | E23: Clear & sunny | F23: Twilight | H23: 222 | I23: The Camera Loves You | J23: Glamour | K23: Twilight (golden hour) | L23: =IF(M23="",0,LEN(M23)-LEN(SUBSTITUTE(M23,",",""))+1) | M23: Peach, Pearl, The Devil | N23: 3
A24: 15 | B24: January | C24: Saturday | D24: New Moon | E24: Clear & sunny | F24: Nightfall | H24: 18 | I24: The Closed Gate | J24: Sigil | K24: Saturday · Dark Moon · Nightfall | L24: =IF(M24="",0,LEN(M24)-LEN(SUBSTITUTE(M24,",",""))+1) | M24: Black ink, Myrrh, Black candle, Dark Moon | N24: 4
A25: 15 | B25: January | C25: Saturday | D25: New Moon | E25: Clear & sunny | F25: Nightfall | H25: 109 | I25: The Quiet Between Stars | J25: Incense | K25: Clear starry night · New Moon | L25: =IF(M25="",0,LEN(M25)-LEN(SUBSTITUTE(M25,",",""))+1) | M25: Lotus, Sandalwood, Clear starry night | N25: 5 | O25: Edmund #96
A26: 16 | B26: January | C26: Sunday | D26: Waxing Crescent | E26: Rain | F26: Sunrise | G26: Yes | H26: 102 | I26: The Slow-Blooming Rose | J26: Sachet | K26: Waxing Crescent | L26: =IF(M26="",0,LEN(M26)-LEN(SUBSTITUTE(M26,",",""))+1) | M26: Green thread, Rosebud, Green candle, Waxing Crescent | N26: 4 | O26: Hester #135
A27: 16 | B27: January | C27: Sunday | D27: Waxing Crescent | E27: Rain | F27: Noon | H27: 55 | I27: Celestial Spotlight | J27: Powder | K27: Sunday · Noon | L27: =IF(M27="",0,LEN(M27)-LEN(SUBSTITUTE(M27,",",""))+1) | M27: Orange blossom | N27: 7
A28: 17 | B28: January | C28: Monday | D28: Waxing Gibbous | E28: Snow | F28: Sunrise | H28: 174 | I28: The Offline Garden | J28: Water | K28: Snow | L28: =IF(M28="",0,LEN(M28)-LEN(SUBSTITUTE(M28,",",""))+1) | M28: Hops, Moss agate, Silver candle, Snow | N28: 2
A29: 17 | B29: January | C29: Monday | D29: Waxing Gibbous | E29: Snow | F29: Noon | H29: 52 | I29: Swanlight | J29: Soap | K29: Monday · Snow | L29: =IF(M29="",0,LEN(M29)-LEN(SUBSTITUTE(M29,",",""))+1) | M29: Selenite, White lily, Temperance | N29: 7
A30: 18 | B30: January | C30: Tuesday | D30: Full Moon | E30: Cloudy | F30: Sunrise | G30: Yes | H30: 4 | I30: Ember of Eden | J30: Oil | K30: Tuesday · Full Moon · Sunrise | L30: =IF(M30="",0,LEN(M30)-LEN(SUBSTITUTE(M30,",",""))+1) | M30: Apple peel, Cardamom, Carnelian, Hibiscus | N30: 6
A31: 18 | B31: January | C31: Tuesday | D31: Full Moon | E31: Cloudy | F31: Noon | H31: 199 | I31: The Brave Little Lantern | J31: Potion | K31: Wolf Moon (January full moon) | L31: =IF(M31="",0,LEN(M31)-LEN(SUBSTITUTE(M31,",",""))+1) | M31: Black salt, Wolf Moon | N31: 6
A32: 19 | B32: January | C32: Wednesday | D32: Waning Gibbous | E32: Snow | F32: Sunrise | H32: 85 | I32: First Spark, First Flame | J32: Rune | K32: Imbolc · Sunrise | L32: =IF(M32="",0,LEN(M32)-LEN(SUBSTITUTE(M32,",",""))+1) | M32: Birch wood, Red paint, Imbolc | N32: 5 | O32: Hester #135
A33: 19 | B33: January | C33: Wednesday | D33: Waning Gibbous | E33: Snow | F33: Noon | H33: 30 | I33: The Hearth's Gentle Flame | J33: Butter | K33: Imbolc | L33: =IF(M33="",0,LEN(M33)-LEN(SUBSTITUTE(M33,",",""))+1) | N33: 7
A34: 20 | B34: January | C34: Thursday | D34: Waning Crescent | E34: Cloudy | F34: Sunrise | H34: 31 | I34: Cloverkiss | J34: Potion | K34: Thursday | L34: =IF(M34="",0,LEN(M34)-LEN(SUBSTITUTE(M34,",",""))+1) | M34: Clover, Four-leaf clover, Green aventurine, Wheel of Fortune | N34: 5 | O34: Morwenna #124
A35: 20 | B35: January | C35: Thursday | D35: Waning Crescent | E35: Cloudy | F35: Noon | H35: 217 | I35: Everyday Stardust | J35: Powder | K35: Any time | L35: =IF(M35="",0,LEN(M35)-LEN(SUBSTITUTE(M35,",",""))+1) | M35: Silver mica, Star anise | N35: 1 | O35: Morwenna #124
A36: 21 | B36: February | C36: Friday | D36: New Moon | E36: Clear & sunny | F36: Sunrise | G36: Yes | H36: 72 | I36: The Open Doorbell | J36: Cookies | K36: Friday · Clear & sunny | L36: =IF(M36="",0,LEN(M36)-LEN(SUBSTITUTE(M36,",",""))+1) | M36: Clear & sunny | N36: 5 | O36: Rosalind #155
A37: 21 | B37: February | C37: Friday | D37: New Moon | E37: Clear & sunny | F37: Nightfall | H37: 59 | I37: Midnight Satin | J37: Sachet | K37: Friday · Dark Moon · Nightfall | L37: =IF(M37="",0,LEN(M37)-LEN(SUBSTITUTE(M37,",",""))+1) | M37: Jasmine, Patchouli, Satin ribbon | N37: 8
A38: 22 | B38: February | C38: Saturday | D38: Waxing Crescent | E38: Cloudy | F38: Sunrise | H38: 200 | I38: The Broken Loop Key | J38: Witch's Ladder | K38: Saturday | L38: =IF(M38="",0,LEN(M38)-LEN(SUBSTITUTE(M38,",",""))+1) | M38: Bay leaf, Purple thread, Grey candle, The Tower | N38: 3 | O38: Felix #34
A39: 22 | B39: February | C39: Saturday | D39: Waxing Crescent | E39: Cloudy | F39: Noon | H39: 210 | I39: The Kind Voice Within | J39: Tea | K39: Any time | L39: =IF(M39="",0,LEN(M39)-LEN(SUBSTITUTE(M39,",",""))+1) | M39: Pink candle, The Empress | N39: 4 | O39: Goldie #219
A40: 23 | B40: February | C40: Sunday | D40: Waxing Gibbous | E40: Snow | F40: Sunrise | H40: 177 | I40: The Nesting Spell | J40: Hand Mirror | K40: Any time | L40: =IF(M40="",0,LEN(M40)-LEN(SUBSTITUTE(M40,",",""))+1) | M40: Nest twig, Rose quartz | N40: 1 | O40: Goldie #7
...

Sheet Learning Check
A1: Due day | B1: Customer | C1: Recipe | D1: New without walk-ins | E1: New with plan | F1: Drop | G1: Flag
A2: 1 | B2: Hester | C2: #111 The Language of Ravens | D2: 3 | E2: 3 | F2: =D2-E2 | G2: =IF(E2>=5,"Check","")
A3: 2 | B3: Edmund | C3: #95 Lavender Hour | D3: 0 | E3: 0 | F3: =D3-E3 | G3: =IF(E3>=5,"Check","")
A4: 3 | B4: Dottie | C4: #153 The Order of Little Things | D4: 0 | E4: 0 | F4: =D4-E4 | G4: =IF(E4>=5,"Check","")
A5: 5 | B5: Goldie | C5: #58 The Velvet Tongue | D5: 3 | E5: 3 | F5: =D5-E5 | G5: =IF(E5>=5,"Check","")
A6: 9 | B6: Dottie | C6: #161 The Fresh Linen Familiar | D6: 2 | E6: 1 | F6: =D6-E6 | G6: =IF(E6>=5,"Check","")
A7: 10 | B7: Rosalind | C7: #23 The Midnight Sentinel | D7: 2 | E7: 2 | F7: =D7-E7 | G7: =IF(E7>=5,"Check","")
A8: 12 | B8: Morwenna | C8: #21 Wayfarer's Ward | D8: 6 | E8: 4 | F8: =D8-E8 | G8: =IF(E8>=5,"Check","")
A9: 12 | B9: Hester | C9: #68 A Thousand Little Lights | D9: 6 | E9: 3 | F9: =D9-E9 | G9: =IF(E9>=5,"Check","")
A10: 16 | B10: Felix | C10: #36 Fortune Favors the Bold | D10: 5 | E10: 4 | F10: =D10-E10 | G10: =IF(E10>=5,"Check","")
A11: 16 | B11: Ivy | C11: #229 The Little Spotlight | D11: 1 | E11: 1 | F11: =D11-E11 | G11: =IF(E11>=5,"Check","")
A12: 17 | B12: Noor | C12: #172 The Sleepy Stardrop | D12: 0 | E12: 0 | F12: =D12-E12 | G12: =IF(E12>=5,"Check","")
A13: 18 | B13: Felix | C13: #151 Rise, Little Flame | D13: 3 | E13: 0 | F13: =D13-E13 | G13: =IF(E13>=5,"Check","")
... A88: 74 | B88: Felix | C88: #220 The Sweet Little Detour | D88: 0 | E88: 0 | F88: =D88-E88 | G88: =IF(E88>=5,"Check","")
B90: Orders with 5+ new parts | D90: =COUNTIF(D2:D88,">=5") | E90: =COUNTIF(E2:E88,">=5")

Sheet Letters
A1: Day | B1: Hour | C1: From | D1: Title | E1: Hints (#) | F1: Ingredient 1 | G1: Keyword 1 | H1: First needed 1 | I1: Why it is hard 1 | J1: Ingredient 2 | K1: Keyword 2 | L1: First needed 2 | M1: Why it is hard 2 | N1: Text
A2: 1 | B2: Sunrise | C2: Mill Lane Apothecary, Wrenmoor | D2: From the apothecary on Mill Lane | E2: 1 | F2: Nettle | G2: healing | H2: Day 1 · #194 The Inner Housekeeper | I2: its entry shows no keyword; searching healing finds 3 other herbs & flowers entries instead | N2: To whoever keeps the Emporium now, Our shelves are bare of nettle, the one herb we can't do without. It stings your fingers when you pick it, and then it builds a worn-out body back up. Nothing does more for healing after a long sickness. I drink it myself, steeped with a little milk, after a long shift behind the counter, on the days I've looked after everyone in Wrenmoor and forgotten to look after me. Could you spare us a bundle or two? We'll pay in honey, as we always did. Agnes, Mill Lane Apothecary, Wrenmoor
A3: 5 | B3: Twilight | C3: The Halloway Baths | D3: From the bathhouse at Halloway | E3: 2 | F3: Epsom salt | G3: cleansing | H3: Day 9 · #161 The Fresh Linen Familiar | I3: its entry shows no keyword; searching cleansing finds 2 other pantry: salts, sugars & baking entries instead | J3: Rose clay | K3: comfort | L3: Day 35 · #98 The Soft Return | M3: its entry shows only self-love; searching comfort finds 3 other pantry: salts, sugars & baking entries instead | N3: To the Emporium, Two orders, if you would. Epsom salt, the bitter white crystals that draw the ache out of tired legs. Our laundry maids grate them into the soap for the towels too; they say it makes washday a proper cleansing and the hours go quicker. And rose clay, the soft pink mud. We press it into little cakes of soap for the old gentlemen who come in after a hard day. They say nothing gives them more comfort before bed. We have been buying poor stuff from Marrowgate and the guests can tell. Mr Hugo Fairweather, Manager, the Halloway Baths
A4: 7 | B4: Noon | C4: The Honeywell Beekeepers | D4: From the beekeepers of Honeywell | E4: 1 | F4: Sweet pea | G4: friendship | H4: Day 12 · #65 Words Like Honey | I4: its entry shows no keyword; searching friendship finds 1 other herbs & flowers entry instead | N4: Dear Emporium, We grow sweet peas along the hive fence, the flower everyone sends when they mean thank you. When two neighbours here fall out and can't find the words to make it up, one of us brews a pot of tea with it and sits them down. It has kept friendship sweet on our lane for forty years. This year the frost took it. If you have dried flowers to spare, we'll pay in comb. Martha Hale and the Honeywell Beekeepers
A5: 8 | B5: Sunrise | C5: St Aldric's Church, Thornbury | D5: From the churchwarden at Thornbury | E5: 2 | F5: Copal | G5: calm | H5: Day 18 · #96 The Last Candle | I5: its entry shows no keyword; searching calm finds 1 other resins & incense entry instead | J5: Black pepper | K5: courage | L5: Day 11 · #50 The Scarlet Entrance | M5: its entry shows no keyword; searching courage finds 1 other spices entry instead | N5: To the Emporium, The vicar has asked me, against my better judgement, to write. He wants copal, the pale sweet resin from overseas. One of our widowers burns a pinch of it every evening at the same hour, and says the house fills with calm, as it did when his wife was alive. The vicar himself grinds black pepper over his eggs before every parish meeting. He says it gives him the courage to hold a room full of people who all think they know better. Our grocer has run out of both. I trust this stays between us. Mr Edgar Penhallow, Churchwarden, Thornbury
A6: 8 | B6: Nightfall | C6: Cloverdale Village School | D6: From the village school in Cloverdale | E6: 2 | F6: Daisy | G6: friendship | H6: Day 12 · #68 A Thousand Little Lights | I6: its entry shows only beginnings; searching friendship finds 7 other herbs & flowers entries instead | J6: Clover | K6: luck | L6: Day 20 · #31 Cloverkiss | M6: its entry shows only friendship; searching luck finds 7 other herbs & flowers entries instead | N6: Dear Emporium, The playground has turned unkind this term, and a new girl starts next week. Here the children make a daisy chain for anyone new; it is how friendship starts in Cloverdale. My predecessor even burned dried ones in the classroom when tempers ran high. The older ones also go hunting for clover, the plain three-leaved kind. Our school cook steeps it into a cordial on sports day, for luck. The frost has spoilt both. Have you any dried? Miss Primrose Dell, Cloverdale Village School
A7: 11 | B7: Nightfall | C7: The Starfall Retreat | D7: From the retreat at Starfall | E7: 1 | F7: Mint | G7: calm | H7: Day 13 · #233 The Casual Enchantment | I7: its entry shows only energy; searching calm finds 4 other herbs & flowers entries instead | N7: Dear Emporium, Half our guests now are young people who come up the mountain to look effortlessly unbothered in their photographs, and are anything but. Our founder served them mint by the jug. She said most people think it only wakes you up, but its real gift is calm: a cool head that doesn't have to try. Have you any dried leaves to spare? Sister Wren, the Starfall Retreat
A8: 13 | B8: Twilight | C8: Lavinia's Bridal Rooms, Kingsmere | D8: From a bridal boutique in Kingsmere | E8: 2 | F8: Orange blossom | G8: joy | H8: Day 16 · #55 Celestial Spotlight | I8: its entry shows no keyword; searching joy finds 7 other herbs & flowers entries instead | J8: White lily | K8: beauty | L8: Day 17 · #52 Swanlight | M8: its entry shows only truth; searching beauty finds 5 other herbs & flowers entries instead | N8: Darling shop, Wedding season is upon us. My brides want orange blossom, dried and ground to a powder for their shoulders, so they shine in every photograph. Their grandmothers said a bride wearing it glows with joy. And for the bride who wants to walk down the aisle like a swan, a soap of white lily. Nothing gives a quiet bride beauty like it. Send whatever you can. Kingsmere does not do things by halves. Lavinia, Lavinia's Bridal Rooms, Kingsmere
A9: 14 | B9: Twilight | C9: Damson Cottage Jams, Plumtree Hollow | D9: From a jam-maker in Plumtree Hollow | E9: 1 | F9: Peridot | G9: growth | H9: Day 21 · #135 The Green Comet | I9: its entry shows no keyword; searching growth finds 1 other crystals entry instead | N9: Hello from the Hollow, When the first green shoots show after a hard winter, my aunt used to sew a peridot into a cloth bag and hang it from the oldest plum tree. She said it was for the first good week of spring, and for growth. The trees never failed her. The bag rotted and the stone is lost in the long grass. Do you sell them? Bessie Damson, Plumtree Hollow
A10: 20 | B10: Nightfall | C10: Crumb & Co. Bakery, Whitcombe | D10: From the bakery in Whitcombe | E10: 2 | F10: Raisins | G10: joy | H10: Day 39 · #90 The Pocket-Sized Triumph | I10: its entry shows no keyword; searching joy finds 2 other fruits entries instead | J10: Cocoa | K10: comfort | L10: Day 26 · #235 The Sweetness Permission | M10: its entry shows no keyword; searching comfort finds 3 other pantry: salts, sugars & baking entries instead | N10: Dear neighbour, Two things for the winter menu. The raisins we bake into the biscuits we give children who finish their reading charts. Such a small win, but the mothers say it is pure joy to them. And cocoa, whipped into the spread for our Saturday buns. Ladies come in saying they really shouldn't, and then they do. Nothing is such a comfort in January. Our supplier in Greywater has gone bust. Could you help? Mrs Ada Crumb, Crumb & Co., Whitcombe
A11: 25 | B11: Sunrise | C11: Thistle & Sons Wandwrights, Elderhollow | D11: From the wandwrights in Elderhollow | E11: 2 | F11: Willow bark | G11: intuition | H11: Day 43 · #99 The Open Palm | I11: its entry shows no keyword; searching intuition finds 2 other herbs & flowers entries instead | J11: Wormwood | K11: transformation | L11: Day 29 · #116 The Phoenix's First Petal | M11: its entry shows no keyword; searching transformation finds 1 other herbs & flowers entry instead | N11: Madam, Two old remedies my grandfather kept. Willow bark, which every grandmother uses for a sore back. He chewed it the winter he lost the old workshop, and said it helped him stop fighting what couldn't be changed. The old witches swore it sharpened their intuition too. And wormwood, which he steeped in a drink every New Year's Eve, to close one chapter and start the next. For transformation, he said, and not for the faint-hearted. If you have either, we would pay well. Silas Thistle, Thistle & Sons Wandwrights, Elderhollow
A12: 27 | B12: Noon | C12: The Crossed Keys Inn, Ashby Cross | D12: From the coaching inn at Ashby Cross | E12: 1 | F12: Wooden die | G12: luck | H12: Day 32 · #232 The Critical-Hit Charm | I12: its entry shows no keyword; searching luck finds 1 other findings & tools entry instead | N12: To the Emporium, Travellers wait here for the coach, and the young ones fill the back room with their long games of dragons and dungeons. One old carter swears by a little wooden die that he had blessed at your shop. He says it gives him luck every time he throws it. The young ones now want one each, for their games night. Do you still bless them? Harry Oakes, landlord, the Crossed Keys, Ashby Cross
A13: 27 | B13: Nightfall | C13: The Coastguard Station, Caldwell-on-Sea | D13: From the coastguard at Caldwell-on-Sea | E13: 1 | F13: Black tourmaline | G13: protection | H13: Day 33 · #29 The Unbroken Quill | I13: its entry shows no keyword; searching protection finds 3 other crystals entries instead | N13: To the Emporium, I paint in my spare hours, little boats mostly, and someone at the station keeps meddling with them. My father kept a piece of black tourmaline on his easel. He said it was the only protection a man's work needs from other people's opinions. Mine went over the side in the last storm. Could you send another? Officer Jory Penrose, Caldwell-on-Sea
A14: 38 | B14: Twilight | C14: Hedge End Farm, Bramblebee | D14: From a farm in Bramblebee | E14: 1 | F14: Rose thorns | G14: boundaries | H14: Day 43 · #70 The Empty Chair | I14: its entry shows no keyword; searching boundaries finds 2 other herbs & flowers entries instead | N14: Hello, My daughter can't let go of a friend who only ever rings when she wants something. My mother would have braided rose thorns into a knotted cord and hung it by the girl's bed. She said it teaches a soft heart its boundaries. I have the cord but not the thorns. Have you a jar? Dora Bramble, Hedge End Farm, Bramblebee
A15: 44 | B15: Twilight | C15: The Cider Fair Committee, Pippin Green | D15: From the cider fair committee in Pippin Green | E15: 1 | F15: Bee pollen | G15: friendship | H15: Day 47 · #75 The Honeybee Feast | I15: its entry shows no keyword | N15: Dear Emporium, Our orchard bees leave bee pollen on everything in May. The old orchard keepers beat it into butter for the fair loaves, and said whoever shares that bread with old friends shares the friendship of the hive. Our hives had a bad year. Could you send a jar for the fair? Rhoda Bell, Cider Fair Committee, Pippin Green
A16: 45 | B16: Nightfall | C16: Mrs Pennywhistle's Sweet Shop, Sugarbrook | D16: From the sweet shop in Sugarbrook | E16: 2 | F16: Pink glitter | G16: self-love | H16: Day 52 · #227 The Cozy-Cute Conjuring | I16: its entry shows no keyword | J16: Pink sprinkles | K16: love | L16: Day 48 · #11 Strawberry Moon | M16: its entry shows no keyword; searching love finds 1 other pantry: salts, sugars & baking entry instead | N16: Dear shop, There's a girl who comes in after school who has been told to tone it down, and it shows. Her gran used to sprinkle pink glitter along the windowsill of her little room, so the whole place looked instantly sweeter, and said it put a bit of self-love back in the girl. And the boys buy cupcakes with pink sprinkles on top to hand to someone they fancy, giggling all the way out. My grandmother called those love on a cake. I'm out of both. I'll send fudge. Mrs Pennywhistle, Sugarbrook
A17: 57 | B17: Nightfall | C17: Old Things, Buttonwick | D17: From an antique shop in Buttonwick | E17: 1 | F17: Square button | G17: play | H17: Day 69 · #215 The Lucky Pixel | I17: its entry shows no keyword; searching play finds 1 other buttons entry instead | N17: Dear neighbour, A house clearance turned up a box of buttons, and among them one odd square button that must be a lost counter from some old board game. I left it on the counter, and the grandchildren wanted to play all afternoon. The little one swears he won every game while it sat by the board. I'll hold it for you. Come by. Mr Ambrose Tuck, Old Things, Buttonwick
A18: 63 | B18: Twilight | C18: Wend Mill, Greywater | D18: From the mill at Greywater | E18: 1 | F18: Cedar chips | G18: home | H18: Day 66 · #3 Two Hearts, One Hearth | I18: its entry shows no keyword; searching home finds 1 other herbs & flowers entry instead | N18: To the Emporium, My mum and dad were married fifty-two years. Dad kept a corked bottle of cedar chips on the mantel, and scattered more in the drawers, until the whole mill house smelled like home. He said it kept them fond of each other through every winter. My wife and I could use some. Could you send a bag? Sam Wend, Wend Mill, Greywater

Sheet Candles
A1: Candle colour | B1: Used in # spells | C1: Image file | D1: Status | E1: Notes
A2: White | B2: =COUNTIF(Recipes!$E$2:$E$241,A2) | C2: candle_white.png | D2: To do
A3: Black | B3: =COUNTIF(Recipes!$E$2:$E$241,A3) | C3: candle_black.png | D3: To do
A4: Red | B4: =COUNTIF(Recipes!$E$2:$E$241,A4) | C4: candle_red.png | D4: To do
A5: Pink | B5: =COUNTIF(Recipes!$E$2:$E$241,A5) | C5: candle_pink.png | D5: To do
A6: Orange | B6: =COUNTIF(Recipes!$E$2:$E$241,A6) | C6: candle_orange.png | D6: To do
A7: Yellow | B7: =COUNTIF(Recipes!$E$2:$E$241,A7) | C7: candle_yellow.png | D7: To do
A8: Gold | B8: =COUNTIF(Recipes!$E$2:$E$241,A8) | C8: candle_gold.png | D8: To do
A9: Green | B9: =COUNTIF(Recipes!$E$2:$E$241,A9) | C9: candle_green.png | D9: To do
A10: Light blue | B10: =COUNTIF(Recipes!$E$2:$E$241,A10) | C10: candle_light_blue.png | D10: To do
A11: Blue | B11: =COUNTIF(Recipes!$E$2:$E$241,A11) | C11: candle_blue.png | D11: To do
A12: Purple | B12: =COUNTIF(Recipes!$E$2:$E$241,A12) | C12: candle_purple.png | D12: To do
A13: Lavender | B13: =COUNTIF(Recipes!$E$2:$E$241,A13) | C13: candle_lavender.png | D13: To do
... A16: Grey | B16: =COUNTIF(Recipes!$E$2:$E$241,A16) | C16: candle_grey.png | D16: To do

Sheet Tarot
A1: Card | B1: Used in # spells | C1: Image file | D1: Status | E1: Notes
A2: The Fool | B2: =COUNTIF(Recipes!$F$2:$F$241,A2) | C2: tarot_the_fool.png | D2: To do
A3: The Magician | B3: =COUNTIF(Recipes!$F$2:$F$241,A3) | C3: tarot_the_magician.png | D3: To do
A4: The High Priestess | B4: =COUNTIF(Recipes!$F$2:$F$241,A4) | C4: tarot_the_high_priestess.png | D4: To do
A5: The Empress | B5: =COUNTIF(Recipes!$F$2:$F$241,A5) | C5: tarot_the_empress.png | D5: To do
A6: The Emperor | B6: =COUNTIF(Recipes!$F$2:$F$241,A6) | C6: tarot_the_emperor.png | D6: To do
A7: The Hierophant | B7: =COUNTIF(Recipes!$F$2:$F$241,A7) | C7: tarot_the_hierophant.png | D7: To do
A8: The Lovers | B8: =COUNTIF(Recipes!$F$2:$F$241,A8) | C8: tarot_the_lovers.png | D8: To do
A9: The Chariot | B9: =COUNTIF(Recipes!$F$2:$F$241,A9) | C9: tarot_the_chariot.png | D9: To do
A10: Strength | B10: =COUNTIF(Recipes!$F$2:$F$241,A10) | C10: tarot_strength.png | D10: To do
A11: The Hermit | B11: =COUNTIF(Recipes!$F$2:$F$241,A11) | C11: tarot_the_hermit.png | D11: To do
A12: Wheel of Fortune | B12: =COUNTIF(Recipes!$F$2:$F$241,A12) | C12: tarot_wheel_of_fortune.png | D12: To do
A13: Justice | B13: =COUNTIF(Recipes!$F$2:$F$241,A13) | C13: tarot_justice.png | D13: To do
... A23: The World | B23: =COUNTIF(Recipes!$F$2:$F$241,A23) | C23: tarot_the_world.png | D23: To do

Sheet Condition Icons
A1: Icon | B1: Group | C1: Image file | D1: Status | E1: Notes
A2: Dark Moon | B2: Moon phase | C2: icon_moon_dark_moon.png | D2: To do
A3: New Moon | B3: Moon phase | C3: icon_moon_new_moon.png | D3: To do
A4: Waxing Crescent | B4: Moon phase | C4: icon_moon_waxing_crescent.png | D4: To do
A5: First Quarter | B5: Moon phase | C5: icon_moon_first_quarter.png | D5: To do
A6: Waxing Gibbous | B6: Moon phase | C6: icon_moon_waxing_gibbous.png | D6: To do
A7: Full Moon | B7: Moon phase | C7: icon_moon_full_moon.png | D7: To do
A8: Waning Gibbous | B8: Moon phase | C8: icon_moon_waning_gibbous.png | D8: To do
A9: Last Quarter | B9: Moon phase | C9: icon_moon_last_quarter.png | D9: To do
A10: Waning Crescent | B10: Moon phase | C10: icon_moon_waning_crescent.png | D10: To do
A11: Wolf Moon | B11: Named moon | C11: icon_named_wolf_moon.png | D11: To do
